<?xml version="1.0"?>
<robot name="four_wheel_robot">
    
    <!-- Base -->
    <link name="base_link">
        <visual>
            <geometry>
                <box size="0.6 0.4 0.1"/>
            </geometry>
            <material name="blue">
                <color rgba="0 0 1 1"/>
            </material>
        </visual>
    </link>

    <!-- Wheels -->
    <link name="front_left_wheel">
        <visual>
            <geometry>
                <cylinder radius="0.1" length="0.05"/>
            </geometry>
            <material name="black">
                <color rgba="0 0 0 1"/>
            </material>
        </visual>
    </link>

    <link name="front_right_wheel">
        <visual>
            <geometry>
                <cylinder radius="0.1" length="0.05"/>
            </geometry>
            <material name="black">
                <color rgba="0 0 0 1"/>
            </material>
        </visual>
    </link>

    <link name="rear_left_wheel">
        <visual>
            <geometry>
                <cylinder radius="0.1" length="0.05"/>
            </geometry>
            <material name="black">
                <color rgba="0 0 0 1"/>
            </material>
        </visual>
    </link>

    <link name="rear_right_wheel">
        <visual>
            <geometry>
                <cylinder radius="0.1" length="0.05"/>
            </geometry>
            <material name="black">
                <color rgba="0 0 0 1"/>
            </material>
        </visual>
    </link>

    <!-- Robotic Arm -->
    <link name="arm_base">
        <visual>
            <geometry>
                <cylinder radius="0.05" length="0.1"/>
            </geometry>
            <material name="red">
                <color rgba="1 0 0 1"/>
            </material>
        </visual>
    </link>

    <link name="arm_link">
        <visual>
            <geometry>
                <box size="0.05 0.3 0.05"/>
            </geometry>
            <material name="gray">
                <color rgba="0.5 0.5 0.5 1"/>
            </material>
        </visual>
    </link>

    <!-- Joints -->
    <joint name="front_left_joint" type="continuous">
        <parent link="base_link"/>
        <child link="front_left_wheel"/>
        <origin xyz="-0.25 0.2 -0.05"/>
        <axis xyz="0 1 0"/>
    </joint>

    <joint name="front_right_joint" type="continuous">
        <parent link="base_link"/>
        <child link="front_right_wheel"/>
        <origin xyz="0.25 0.2 -0.05"/>
        <axis xyz="0 1 0"/>
    </joint>

    <joint name="rear_left_joint" type="continuous">
        <parent link="base_link"/>
        <child link="rear_left_wheel"/>
        <origin xyz="-0.25 -0.2 -0.05"/>
        <axis xyz="0 1 0"/>
    </joint>

    <joint name="rear_right_joint" type="continuous">
        <parent link="base_link"/>
        <child link="rear_right_wheel"/>
        <origin xyz="0.25 -0.2 -0.05"/>
        <axis xyz="0 1 0"/>
    </joint>

    <joint name="arm_base_joint" type="fixed">
        <parent link="base_link"/>
        <child link="arm_base"/>
        <origin xyz="0 0 0.05"/>
    </joint>

    <joint name="arm_joint" type="revolute">
        <parent link="arm_base"/>
        <child link="arm_link"/>
        <origin xyz="0 0 0.1"/>
        <axis xyz="0 1 0"/>
        <limit effort="10" velocity="1.0" lower="-1.5" upper="1.5"/>
    </joint>

</robot>
